{"errorMessage": "Parameter validation failed:\nInvalid type for parameter AttributeUpdates.Name, value: Outgoing, type: <class 'str'>, valid types: <class 'dict'>", "errorType": "ParamValidationError", "stackTrace": ["  File \"/var/task/app.py\", line 63, in lambda_handler\n    response = table.update_item(\n", "  File \"/var/task/boto3/resources/factory.py\", line 520, in do_action\n    response = action(self, *args, **kwargs)\n", "  File \"/var/task/boto3/resources/action.py\", line 83, in __call__\n    response = getattr(parent.meta.client, operation_name)(*args, **params)\n", "  File \"/var/task/botocore/client.py\", line 386, in _api_call\n    return self._make_api_call(operation_name, kwargs)\n", "  File \"/var/task/botocore/client.py\", line 677, in _make_api_call\n    request_dict = self._convert_to_request_dict(\n", "  File \"/var/task/botocore/client.py\", line 725, in _convert_to_request_dict\n    request_dict = self._serializer.serialize_to_request(\n", "  File \"/var/task/botocore/validate.py\", line 319, in serialize_to_request\n    raise ParamValidationError(report=report.generate_report())\n"]}